Workbook

Sheet 출하일보전송용260416
A1: 순번 | B1: 일자 | C1: 거래처 | D1: 납품처 | E1: 모델 | F1: 생산수 | G1: 출하수 | H1: 차량(No) | I1: 기준중량(g) | J1: 출하중량(g) | K1: 단가 | L1: 매출액 | M1: 2.5운반비 | N1: 5.0운반비 | O1: 운반비 | P1: 추가운반비 | Q1: 운반비합계 | R1: 금형자산 | S1: 제품군
A2: 1 | B2: 46128 | C2: 뉴옵틱스 | D2: 뉴옵틱스 | E2: 49SB/SONAGI | F2: 42 | H2: 삼일5 | I2: =IF(E2="","",VLOOKUP(E2,[1]DATA!$A$2:$AG$2452,5,FALSE)) -> 1620 | J2: =IF(E2="","",(G2*I2/1000)) -> 0 | K2: =IF(E2="","",SUMIFS([2]단가!$E:$E,[2]단가!$A:$A,출하일보전송용260416!$C2,[2]단가!$B:$B,출하일보전송용260416!$E2)) -> #VALUE! | L2: =IF(E2="","",(G2*K2)) -> #VALUE! | M2: =IF(H2="","",IF(H2<50,VLOOKUP(C2,[1]운반비기준!$A$2:$D$3036,3,FALSE))) -> FALSE | N2: 180000 | O2: =IF(H2="","",(M2+N2)) -> 180000 | Q2: =IF(H2="","",(O2+P2)) -> 180000 | R2: =IF(E2="","",VLOOKUP(E2,[1]DATA!$A$2:$AG$2452,10,FALSE)) -> 뉴옵틱스 | S2: =IF(E2="","",VLOOKUP(E2,[1]DATA!$A$2:$AG$2452,2,FALSE)) -> SET
A3: =IF(E3="","",(A2+1)) -> 2 | B3: =IF(E3="","",(B2)) -> 46128 | C3: 뉴옵틱스 | D3: 뉴옵틱스 | E3: 55XS2C-M | F3: 60 | I3: =IF(E3="","",VLOOKUP(E3,[1]DATA!$A$2:$AG$2452,5,FALSE)) -> 4398 | J3: =IF(E3="","",(G3*I3/1000)) -> 0 | K3: =IF(E3="","",SUMIFS([2]단가!$E:$E,[2]단가!$A:$A,출하일보전송용260416!$C3,[2]단가!$B:$B,출하일보전송용260416!$E3)) -> #VALUE! | L3: =IF(E3="","",(G3*K3)) -> #VALUE! | M3: =IF(H3="","",IF(H3<50,VLOOKUP(C3,[1]운반비기준!$A$2:$D$3036,3,FALSE))) | N3: =IF(H3="","",IF(H3>51,VLOOKUP(C3,[1]운반비기준!$A$2:$D$3036,4,FALSE))) | O3: =IF(H3="","",(M3+N3)) | Q3: =IF(H3="","",(O3+P3)) | R3: =IF(E3="","",VLOOKUP(E3,[1]DATA!$A$2:$AG$2452,10,FALSE)) -> 뉴옵틱스 | S3: =IF(E3="","",VLOOKUP(E3,[1]DATA!$A$2:$AG$2452,2,FALSE)) -> SET
A4: =IF(E4="","",(A3+1)) -> 3 | B4: =IF(E4="","",(B3)) -> 46128 | C4: 가화텍 | D4: 가화텍창고 | E4: 채소정식판64구 | F4: 200 | H4: 삼일5 | I4: =IF(E4="","",VLOOKUP(E4,[1]DATA!$A$2:$AG$2452,5,FALSE)) -> 350 | J4: =IF(E4="","",(G4*I4/1000)) -> 0 | K4: =IF(E4="","",SUMIFS([2]단가!$E:$E,[2]단가!$A:$A,출하일보전송용260416!$C4,[2]단가!$B:$B,출하일보전송용260416!$E4)) -> #VALUE! | L4: =IF(E4="","",(G4*K4)) -> #VALUE! | M4: =IF(H4="","",IF(H4<50,VLOOKUP(C4,[1]운반비기준!$A$2:$D$3036,3,FALSE))) -> FALSE | N4: 140000 | O4: =IF(H4="","",(M4+N4)) -> 140000 | Q4: =IF(H4="","",(O4+P4)) -> 140000 | R4: =IF(E4="","",VLOOKUP(E4,[1]DATA!$A$2:$AG$2452,10,FALSE)) -> 가화텍 | S4: =IF(E4="","",VLOOKUP(E4,[1]DATA!$A$2:$AG$2452,2,FALSE)) -> SET
A5: =IF(E5="","",(A4+1)) -> 4 | B5: =IF(E5="","",(B4)) -> 46128 | C5: 가화텍 | D5: 가화텍창고 | E5: 다목적정식판(33배) | F5: 200 | I5: =IF(E5="","",VLOOKUP(E5,[1]DATA!$A$2:$AG$2452,5,FALSE)) -> 316 | J5: =IF(E5="","",(G5*I5/1000)) -> 0 | K5: =IF(E5="","",SUMIFS([2]단가!$E:$E,[2]단가!$A:$A,출하일보전송용260416!$C5,[2]단가!$B:$B,출하일보전송용260416!$E5)) -> #VALUE! | L5: =IF(E5="","",(G5*K5)) -> #VALUE! | M5: =IF(H5="","",IF(H5<50,VLOOKUP(C5,[1]운반비기준!$A$2:$D$3036,3,FALSE))) | N5: =IF(H5="","",IF(H5>51,VLOOKUP(C5,[1]운반비기준!$A$2:$D$3036,4,FALSE))) | O5: =IF(H5="","",(M5+N5)) | Q5: =IF(H5="","",(O5+P5)) | R5: =IF(E5="","",VLOOKUP(E5,[1]DATA!$A$2:$AG$2452,10,FALSE)) -> 가화텍 | S5: =IF(E5="","",VLOOKUP(E5,[1]DATA!$A$2:$AG$2452,2,FALSE)) -> SET
A6: =IF(E6="","",(A5+1)) -> 5 | B6: =IF(E6="","",(B5)) -> 46128 | C6: 가화텍 | D6: 가화텍창고 | E6: 분무경2호베드 | F6: 100 | I6: =IF(E6="","",VLOOKUP(E6,[1]DATA!$A$2:$AG$2452,5,FALSE)) -> 1055 | J6: =IF(E6="","",(G6*I6/1000)) -> 0 | K6: =IF(E6="","",SUMIFS([2]단가!$E:$E,[2]단가!$A:$A,출하일보전송용260416!$C6,[2]단가!$B:$B,출하일보전송용260416!$E6)) -> #VALUE! | L6: =IF(E6="","",(G6*K6)) -> #VALUE! | M6: =IF(H6="","",IF(H6<50,VLOOKUP(C6,[1]운반비기준!$A$2:$D$3036,3,FALSE))) | N6: =IF(H6="","",IF(H6>51,VLOOKUP(C6,[1]운반비기준!$A$2:$D$3036,4,FALSE))) | O6: =IF(H6="","",(M6+N6)) | Q6: =IF(H6="","",(O6+P6)) | R6: =IF(E6="","",VLOOKUP(E6,[1]DATA!$A$2:$AG$2452,10,FALSE)) -> 가화텍 | S6: =IF(E6="","",VLOOKUP(E6,[1]DATA!$A$2:$AG$2452,2,FALSE)) -> SET
A7: =IF(E7="","",(A6+1)) -> 6 | B7: =IF(E7="","",(B6)) -> 46128 | C7: 가화텍 | D7: 가화텍창고 | E7: 다목적3호고#2(33배) | F7: 100 | I7: =IF(E7="","",VLOOKUP(E7,[1]DATA!$A$2:$AG$2452,5,FALSE)) -> 1840 | J7: =IF(E7="","",(G7*I7/1000)) -> 0 | K7: =IF(E7="","",SUMIFS([2]단가!$E:$E,[2]단가!$A:$A,출하일보전송용260416!$C7,[2]단가!$B:$B,출하일보전송용260416!$E7)) -> #VALUE! | L7: =IF(E7="","",(G7*K7)) -> #VALUE! | M7: =IF(H7="","",IF(H7<50,VLOOKUP(C7,[1]운반비기준!$A$2:$D$3036,3,FALSE))) | N7: =IF(H7="","",IF(H7>51,VLOOKUP(C7,[1]운반비기준!$A$2:$D$3036,4,FALSE))) | O7: =IF(H7="","",(M7+N7)) | Q7: =IF(H7="","",(O7+P7)) | R7: =IF(E7="","",VLOOKUP(E7,[1]DATA!$A$2:$AG$2452,10,FALSE)) -> 가화텍 | S7: =IF(E7="","",VLOOKUP(E7,[1]DATA!$A$2:$AG$2452,2,FALSE)) -> SET
A8: =IF(E8="","",(A7+1)) -> 7 | B8: =IF(E8="","",(B7)) -> 46128 | C8: 가화텍 | D8: 가화텍창고 | E8: N배지경2호베드 | F8: 150 | I8: =IF(E8="","",VLOOKUP(E8,[1]DATA!$A$2:$AG$2452,5,FALSE)) -> 625 | J8: =IF(E8="","",(G8*I8/1000)) -> 0 | K8: =IF(E8="","",SUMIFS([2]단가!$E:$E,[2]단가!$A:$A,출하일보전송용260416!$C8,[2]단가!$B:$B,출하일보전송용260416!$E8)) -> #VALUE! | L8: =IF(E8="","",(G8*K8)) -> #VALUE! | M8: =IF(H8="","",IF(H8<50,VLOOKUP(C8,[1]운반비기준!$A$2:$D$3036,3,FALSE))) | N8: =IF(H8="","",IF(H8>51,VLOOKUP(C8,[1]운반비기준!$A$2:$D$3036,4,FALSE))) | O8: =IF(H8="","",(M8+N8)) | Q8: =IF(H8="","",(O8+P8)) | R8: =IF(E8="","",VLOOKUP(E8,[1]DATA!$A$2:$AG$2452,10,FALSE)) -> 가화텍 | S8: =IF(E8="","",VLOOKUP(E8,[1]DATA!$A$2:$AG$2452,2,FALSE)) -> SET
A9: =IF(E9="","",(A8+1)) -> 8 | B9: =IF(E9="","",(B8)) -> 46128 | C9: 한국이노팩 | D9: 보령수산업협동조합 | E9: SI-7.5K | F9: 1200 | H9: 삼일5 | I9: =IF(E9="","",VLOOKUP(E9,[1]DATA!$A$2:$AG$2452,5,FALSE)) -> 210 | J9: =IF(E9="","",(G9*I9/1000)) -> 0 | K9: =IF(E9="","",SUMIFS([2]단가!$E:$E,[2]단가!$A:$A,출하일보전송용260416!$C9,[2]단가!$B:$B,출하일보전송용260416!$E9)) -> #VALUE! | L9: =IF(E9="","",(G9*K9)) -> #VALUE! | M9: =IF(H9="","",IF(H9<50,VLOOKUP(C9,[1]운반비기준!$A$2:$D$3036,3,FALSE))) -> FALSE | N9: 220000 | O9: =IF(H9="","",(M9+N9)) -> 220000 | Q9: =IF(H9="","",(O9+P9)) -> 220000 | R9: =IF(E9="","",VLOOKUP(E9,[1]DATA!$A$2:$AG$2452,10,FALSE)) -> 삼일이노팩 | S9: =IF(E9="","",VLOOKUP(E9,[1]DATA!$A$2:$AG$2452,2,FALSE)) -> BOX
A10: =IF(E10="","",(A9+1)) -> 9 | B10: =IF(E10="","",(B9)) -> 46128 | C10: 코웨이/포천공장 | D10: 후문 | E10: SWITCH | F10: 1350 | H10: 501 | I10: =IF(E10="","",VLOOKUP(E10,[1]DATA!$A$2:$AG$2452,5,FALSE)) -> 89 | J10: =IF(E10="","",(G10*I10/1000)) -> 0 | K10: =IF(E10="","",SUMIFS([2]단가!$E:$E,[2]단가!$A:$A,출하일보전송용260416!$C10,[2]단가!$B:$B,출하일보전송용260416!$E10)) -> #VALUE! | L10: =IF(E10="","",(G10*K10)) -> #VALUE! | M10: =IF(H10="","",IF(H10<50,VLOOKUP(C10,[1]운반비기준!$A$2:$D$3036,3,FALSE))) -> FALSE | N10: =IF(H10="","",IF(H10>51,VLOOKUP(C10,[1]운반비기준!$A$2:$D$3036,4,FALSE))) -> 238000 | O10: =IF(H10="","",(M10+N10)) -> 238000 | Q10: =IF(H10="","",(O10+P10)) -> 238000 | R10: =IF(E10="","",VLOOKUP(E10,[1]DATA!$A$2:$AG$2452,10,FALSE)) -> 코웨이 | S10: =IF(E10="","",VLOOKUP(E10,[1]DATA!$A$2:$AG$2452,2,FALSE)) -> SET
A11: =IF(E11="","",(A10+1)) -> 10 | B11: =IF(E11="","",(B10)) -> 46128 | C11: 중부스티로폼 | D11: 중부스티로폼 | E11: SI-0.5K#2 | F11: 280 | H11: 500 | I11: =IF(E11="","",VLOOKUP(E11,[1]DATA!$A$2:$AG$2452,5,FALSE)) -> 53 | J11: =IF(E11="","",(G11*I11/1000)) -> 0 | K11: =IF(E11="","",SUMIFS([2]단가!$E:$E,[2]단가!$A:$A,출하일보전송용260416!$C11,[2]단가!$B:$B,출하일보전송용260416!$E11)) -> #VALUE! | L11: =IF(E11="","",(G11*K11)) -> #VALUE! | M11: =IF(H11="","",IF(H11<50,VLOOKUP(C11,[1]운반비기준!$A$2:$D$3036,3,FALSE))) -> FALSE | N11: =IF(H11="","",IF(H11>51,VLOOKUP(C11,[1]운반비기준!$A$2:$D$3036,4,FALSE))) -> 249000 | O11: =IF(H11="","",(M11+N11)) -> 249000 | Q11: =IF(H11="","",(O11+P11)) -> 249000 | R11: =IF(E11="","",VLOOKUP(E11,[1]DATA!$A$2:$AG$2452,10,FALSE)) -> 삼일이노팩 | S11: =IF(E11="","",VLOOKUP(E11,[1]DATA!$A$2:$AG$2452,2,FALSE)) -> BOX
A12: =IF(E12="","",(A11+1)) -> 11 | B12: =IF(E12="","",(B11)) -> 46128 | C12: 중부스티로폼 | D12: 중부스티로폼 | E12: JB딸기1K(1호) | F12: 2400 | I12: =IF(E12="","",VLOOKUP(E12,[1]DATA!$A$2:$AG$2452,5,FALSE)) -> 30 | J12: =IF(E12="","",(G12*I12/1000)) -> 0 | K12: =IF(E12="","",SUMIFS([2]단가!$E:$E,[2]단가!$A:$A,출하일보전송용260416!$C12,[2]단가!$B:$B,출하일보전송용260416!$E12)) -> #VALUE! | L12: =IF(E12="","",(G12*K12)) -> #VALUE! | M12: =IF(H12="","",IF(H12<50,VLOOKUP(C12,[1]운반비기준!$A$2:$D$3036,3,FALSE))) | N12: =IF(H12="","",IF(H12>51,VLOOKUP(C12,[1]운반비기준!$A$2:$D$3036,4,FALSE))) | O12: =IF(H12="","",(M12+N12)) | Q12: =IF(H12="","",(O12+P12)) | R12: =IF(E12="","",VLOOKUP(E12,[1]DATA!$A$2:$AG$2452,10,FALSE)) -> 중부스치로폼 | S12: =IF(E12="","",VLOOKUP(E12,[1]DATA!$A$2:$AG$2452,2,FALSE)) -> BOX
A13: =IF(E13="","",(A12+1)) -> 12 | B13: =IF(E13="","",(B12)) -> 46128 | C13: 중부스티로폼 | D13: 중부스티로폼 | E13: JB블루베리1-2 | F13: 420 | I13: =IF(E13="","",VLOOKUP(E13,[1]DATA!$A$2:$AG$2452,5,FALSE)) -> 150 | J13: =IF(E13="","",(G13*I13/1000)) -> 0 | K13: =IF(E13="","",SUMIFS([2]단가!$E:$E,[2]단가!$A:$A,출하일보전송용260416!$C13,[2]단가!$B:$B,출하일보전송용260416!$E13)) -> #VALUE! | L13: =IF(E13="","",(G13*K13)) -> #VALUE! | M13: =IF(H13="","",IF(H13<50,VLOOKUP(C13,[1]운반비기준!$A$2:$D$3036,3,FALSE))) | N13: =IF(H13="","",IF(H13>51,VLOOKUP(C13,[1]운반비기준!$A$2:$D$3036,4,FALSE))) | O13: =IF(H13="","",(M13+N13)) | Q13: =IF(H13="","",(O13+P13)) | R13: =IF(E13="","",VLOOKUP(E13,[1]DATA!$A$2:$AG$2452,10,FALSE)) -> 중부스치로폼 | S13: =IF(E13="","",VLOOKUP(E13,[1]DATA!$A$2:$AG$2452,2,FALSE)) -> BOX
A14: =IF(E14="","",(A13+1)) -> 13 | B14: =IF(E14="","",(B13)) -> 46128 | C14: 중부스티로폼 | D14: 중부스티로폼 | E14: JB15K | F14: 140 | I14: =IF(E14="","",VLOOKUP(E14,[1]DATA!$A$2:$AG$2452,5,FALSE)) -> 360 | J14: =IF(E14="","",(G14*I14/1000)) -> 0 | K14: =IF(E14="","",SUMIFS([2]단가!$E:$E,[2]단가!$A:$A,출하일보전송용260416!$C14,[2]단가!$B:$B,출하일보전송용260416!$E14)) -> #VALUE! | L14: =IF(E14="","",(G14*K14)) -> #VALUE! | M14: =IF(H14="","",IF(H14<50,VLOOKUP(C14,[1]운반비기준!$A$2:$D$3036,3,FALSE))) | N14: =IF(H14="","",IF(H14>51,VLOOKUP(C14,[1]운반비기준!$A$2:$D$3036,4,FALSE))) | O14: =IF(H14="","",(M14+N14)) | Q14: =IF(H14="","",(O14+P14)) | R14: =IF(E14="","",VLOOKUP(E14,[1]DATA!$A$2:$AG$2452,10,FALSE)) -> 중부스치로폼 | S14: =IF(E14="","",VLOOKUP(E14,[1]DATA!$A$2:$AG$2452,2,FALSE)) -> BOX
A15: =IF(E15="","",(A14+1)) -> 14 | B15: =IF(E15="","",(B14)) -> 46128 | C15: 반디 | D15: 반디 | E15: DW-1호#3 | F15: 1200 | H15: 528 | I15: =IF(E15="","",VLOOKUP(E15,[1]DATA!$A$2:$AG$2452,5,FALSE)) -> 190 | J15: =IF(E15="","",(G15*I15/1000)) -> 0 | K15: =IF(E15="","",SUMIFS([2]단가!$E:$E,[2]단가!$A:$A,출하일보전송용260416!$C15,[2]단가!$B:$B,출하일보전송용260416!$E15)) -> #VALUE! | L15: =IF(E15="","",(G15*K15)) -> #VALUE! | M15: =IF(H15="","",IF(H15<50,VLOOKUP(C15,[1]운반비기준!$A$2:$D$3036,3,FALSE))) -> FALSE | N15: =IF(H15="","",IF(H15>51,VLOOKUP(C15,[1]운반비기준!$A$2:$D$3036,4,FALSE))) -> 136000 | O15: =IF(H15="","",(M15+N15)) -> 136000 | Q15: =IF(H15="","",(O15+P15)) -> 136000 | R15: =IF(E15="","",VLOOKUP(E15,[1]DATA!$A$2:$AG$2452,10,FALSE)) -> 삼일이노팩 | S15: =IF(E15="","",VLOOKUP(E15,[1]DATA!$A$2:$AG$2452,2,FALSE)) -> BOX
A16: =IF(E16="","",(A15+1)) -> 15 | B16: =IF(E16="","",(B15)) -> 46128 | C16: 캐논코리아 | D16: 2층,E/V앞 | E16: T499-SET#3 | F16: 464 | H16: 11 | I16: =IF(E16="","",VLOOKUP(E16,[1]DATA!$A$2:$AG$2452,5,FALSE)) -> 155 | J16: =IF(E16="","",(G16*I16/1000)) -> 0 | K16: =IF(E16="","",SUMIFS([2]단가!$E:$E,[2]단가!$A:$A,출하일보전송용260416!$C16,[2]단가!$B:$B,출하일보전송용260416!$E16)) -> #VALUE! | L16: =IF(E16="","",(G16*K16)) -> #VALUE! | M16: =IF(H16="","",IF(H16<50,VLOOKUP(C16,[1]운반비기준!$A$2:$D$3036,3,FALSE))) -> 80000 | N16: =IF(H16="","",IF(H16>51,VLOOKUP(C16,[1]운반비기준!$A$2:$D$3036,4,FALSE))) -> FALSE | O16: =IF(H16="","",(M16+N16)) -> 80000 | Q16: =IF(H16="","",(O16+P16)) -> 80000 | R16: =IF(E16="","",VLOOKUP(E16,[1]DATA!$A$2:$AG$2452,10,FALSE)) -> 캐논 | S16: =IF(E16="","",VLOOKUP(E16,[1]DATA!$A$2:$AG$2452,2,FALSE)) -> SET
A17: =IF(E17="","",(A16+1)) -> 16 | B17: =IF(E17="","",(B16)) -> 46128 | C17: CJ대한통운/형제식품 | D17: 형제식품 | E17: 다용도5K | F17: 160 | H17: 5 | I17: =IF(E17="","",VLOOKUP(E17,[1]DATA!$A$2:$AG$2452,5,FALSE)) -> 100 | J17: =IF(E17="","",(G17*I17/1000)) -> 0 | K17: =IF(E17="","",SUMIFS([2]단가!$E:$E,[2]단가!$A:$A,출하일보전송용260416!$C17,[2]단가!$B:$B,출하일보전송용260416!$E17)) -> #VALUE! | L17: =IF(E17="","",(G17*K17)) -> #VALUE! | M17: =IF(H17="","",IF(H17<50,VLOOKUP(C17,[1]운반비기준!$A$2:$D$3036,3,FALSE))) -> 118000 | N17: =IF(H17="","",IF(H17>51,VLOOKUP(C17,[1]운반비기준!$A$2:$D$3036,4,FALSE))) -> FALSE | O17: =IF(H17="","",(M17+N17)) -> 118000 | Q17: =IF(H17="","",(O17+P17)) -> 118000 | R17: =IF(E17="","",VLOOKUP(E17,[1]DATA!$A$2:$AG$2452,10,FALSE)) -> 삼일이노팩 | S17: =IF(E17="","",VLOOKUP(E17,[1]DATA!$A$2:$AG$2452,2,FALSE)) -> BOX
A18: =IF(E18="","",(A17+1)) -> 17 | B18: =IF(E18="","",(B17)) -> 46128 | C18: CJ대한통운/형제식품 | D18: 형제식품 | E18: SI-느타리2K | F18: 240 | I18: =IF(E18="","",VLOOKUP(E18,[1]DATA!$A$2:$AG$2452,5,FALSE)) -> 87 | J18: =IF(E18="","",(G18*I18/1000)) -> 0 | K18: =IF(E18="","",SUMIFS([2]단가!$E:$E,[2]단가!$A:$A,출하일보전송용260416!$C18,[2]단가!$B:$B,출하일보전송용260416!$E18)) -> #VALUE! | L18: =IF(E18="","",(G18*K18)) -> #VALUE! | M18: =IF(H18="","",IF(H18<50,VLOOKUP(C18,[1]운반비기준!$A$2:$D$3036,3,FALSE))) | N18: =IF(H18="","",IF(H18>51,VLOOKUP(C18,[1]운반비기준!$A$2:$D$3036,4,FALSE))) | O18: =IF(H18="","",(M18+N18)) | Q18: =IF(H18="","",(O18+P18)) | R18: =IF(E18="","",VLOOKUP(E18,[1]DATA!$A$2:$AG$2452,10,FALSE)) -> 삼일이노팩 | S18: =IF(E18="","",VLOOKUP(E18,[1]DATA!$A$2:$AG$2452,2,FALSE)) -> BOX
A19: =IF(E19="","",(A18+1)) -> 18 | B19: =IF(E19="","",(B18)) -> 46128 | C19: CJ대한통운/형제식품 | D19: 형제식품 | E19: 다용도SG-3K-2(형합) | F19: 40 | I19: =IF(E19="","",VLOOKUP(E19,[1]DATA!$A$2:$AG$2452,5,FALSE)) -> 140 | J19: =IF(E19="","",(G19*I19/1000)) -> 0 | K19: =IF(E19="","",SUMIFS([2]단가!$E:$E,[2]단가!$A:$A,출하일보전송용260416!$C19,[2]단가!$B:$B,출하일보전송용260416!$E19)) -> #VALUE! | L19: =IF(E19="","",(G19*K19)) -> #VALUE! | M19: =IF(H19="","",IF(H19<50,VLOOKUP(C19,[1]운반비기준!$A$2:$D$3036,3,FALSE))) | N19: =IF(H19="","",IF(H19>51,VLOOKUP(C19,[1]운반비기준!$A$2:$D$3036,4,FALSE))) | O19: =IF(H19="","",(M19+N19)) | Q19: =IF(H19="","",(O19+P19)) | R19: =IF(E19="","",VLOOKUP(E19,[1]DATA!$A$2:$AG$2452,10,FALSE)) -> 삼일이노팩 | S19: =IF(E19="","",VLOOKUP(E19,[1]DATA!$A$2:$AG$2452,2,FALSE)) -> BOX
A20: =IF(E20="","",(A19+1)) -> 19 | B20: =IF(E20="","",(B19)) -> 46128 | C20: CJ대한통운/형제식품 | D20: 형제식품 | E20: JB4K | F20: 30 | I20: =IF(E20="","",VLOOKUP(E20,[1]DATA!$A$2:$AG$2452,5,FALSE)) -> 130 | J20: =IF(E20="","",(G20*I20/1000)) -> 0 | K20: =IF(E20="","",SUMIFS([2]단가!$E:$E,[2]단가!$A:$A,출하일보전송용260416!$C20,[2]단가!$B:$B,출하일보전송용260416!$E20)) -> #VALUE! | L20: =IF(E20="","",(G20*K20)) -> #VALUE! | M20: =IF(H20="","",IF(H20<50,VLOOKUP(C20,[1]운반비기준!$A$2:$D$3036,3,FALSE))) | N20: =IF(H20="","",IF(H20>51,VLOOKUP(C20,[1]운반비기준!$A$2:$D$3036,4,FALSE))) | O20: =IF(H20="","",(M20+N20)) | Q20: =IF(H20="","",(O20+P20)) | R20: =IF(E20="","",VLOOKUP(E20,[1]DATA!$A$2:$AG$2452,10,FALSE)) -> 중부스치로폼 | S20: =IF(E20="","",VLOOKUP(E20,[1]DATA!$A$2:$AG$2452,2,FALSE)) -> BOX
A21: =IF(E21="","",(A20+1)) -> 20 | B21: =IF(E21="","",(B20)) -> 46128 | C21: CJ대한통운/형제식품 | D21: 형제식품 | E21: KURLY-10#2 | F21: 20 | I21: =IF(E21="","",VLOOKUP(E21,[1]DATA!$A$2:$AG$2452,5,FALSE)) -> 280 | J21: =IF(E21="","",(G21*I21/1000)) -> 0 | K21: =IF(E21="","",SUMIFS([2]단가!$E:$E,[2]단가!$A:$A,출하일보전송용260416!$C21,[2]단가!$B:$B,출하일보전송용260416!$E21)) -> #VALUE! | L21: =IF(E21="","",(G21*K21)) -> #VALUE! | M21: =IF(H21="","",IF(H21<50,VLOOKUP(C21,[1]운반비기준!$A$2:$D$3036,3,FALSE))) | N21: =IF(H21="","",IF(H21>51,VLOOKUP(C21,[1]운반비기준!$A$2:$D$3036,4,FALSE))) | O21: =IF(H21="","",(M21+N21)) | Q21: =IF(H21="","",(O21+P21)) | R21: =IF(E21="","",VLOOKUP(E21,[1]DATA!$A$2:$AG$2452,10,FALSE)) -> 삼일이노팩 | S21: =IF(E21="","",VLOOKUP(E21,[1]DATA!$A$2:$AG$2452,2,FALSE)) -> BOX
A22: =IF(E22="","",(A21+1)) -> 21 | B22: =IF(E22="","",(B21)) -> 46128 | C22: CJ대한통운/형제식품 | D22: 형제식품 | E22: JB4-2K | F22: 128 | I22: =IF(E22="","",VLOOKUP(E22,[1]DATA!$A$2:$AG$2452,5,FALSE)) -> 156 | J22: =IF(E22="","",(G22*I22/1000)) -> 0 | K22: =IF(E22="","",SUMIFS([2]단가!$E:$E,[2]단가!$A:$A,출하일보전송용260416!$C22,[2]단가!$B:$B,출하일보전송용260416!$E22)) -> #VALUE! | L22: =IF(E22="","",(G22*K22)) -> #VALUE! | M22: =IF(H22="","",IF(H22<50,VLOOKUP(C22,[1]운반비기준!$A$2:$D$3036,3,FALSE))) | N22: =IF(H22="","",IF(H22>51,VLOOKUP(C22,[1]운반비기준!$A$2:$D$3036,4,FALSE))) | O22: =IF(H22="","",(M22+N22)) | Q22: =IF(H22="","",(O22+P22)) | R22: =IF(E22="","",VLOOKUP(E22,[1]DATA!$A$2:$AG$2452,10,FALSE)) -> 중부스치로폼 | S22: =IF(E22="","",VLOOKUP(E22,[1]DATA!$A$2:$AG$2452,2,FALSE)) -> BOX
A23: =IF(E23="","",(A22+1)) -> 22 | B23: =IF(E23="","",(B22)) -> 46128 | C23: CJ대한통운/형제식품 | D23: 형제식품 | E23: JB15K | F23: 12 | I23: =IF(E23="","",VLOOKUP(E23,[1]DATA!$A$2:$AG$2452,5,FALSE)) -> 360 | J23: =IF(E23="","",(G23*I23/1000)) -> 0 | K23: =IF(E23="","",SUMIFS([2]단가!$E:$E,[2]단가!$A:$A,출하일보전송용260416!$C23,[2]단가!$B:$B,출하일보전송용260416!$E23)) -> #VALUE! | L23: =IF(E23="","",(G23*K23)) -> #VALUE! | M23: =IF(H23="","",IF(H23<50,VLOOKUP(C23,[1]운반비기준!$A$2:$D$3036,3,FALSE))) | N23: =IF(H23="","",IF(H23>51,VLOOKUP(C23,[1]운반비기준!$A$2:$D$3036,4,FALSE))) | O23: =IF(H23="","",(M23+N23)) | Q23: =IF(H23="","",(O23+P23)) | R23: =IF(E23="","",VLOOKUP(E23,[1]DATA!$A$2:$AG$2452,10,FALSE)) -> 중부스치로폼 | S23: =IF(E23="","",VLOOKUP(E23,[1]DATA!$A$2:$AG$2452,2,FALSE)) -> BOX
A24: =IF(E24="","",(A23+1)) -> 23 | B24: =IF(E24="","",(B23)) -> 46128 | C24: CJ대한통운/형제식품 | D24: 형제식품 | E24: NHD-4#2 | F24: 50 | I24: =IF(E24="","",VLOOKUP(E24,[1]DATA!$A$2:$AG$2452,5,FALSE)) -> 122 | J24: =IF(E24="","",(G24*I24/1000)) -> 0 | K24: =IF(E24="","",SUMIFS([2]단가!$E:$E,[2]단가!$A:$A,출하일보전송용260416!$C24,[2]단가!$B:$B,출하일보전송용260416!$E24)) -> #VALUE! | L24: =IF(E24="","",(G24*K24)) -> #VALUE! | M24: =IF(H24="","",IF(H24<50,VLOOKUP(C24,[1]운반비기준!$A$2:$D$3036,3,FALSE))) | N24: =IF(H24="","",IF(H24>51,VLOOKUP(C24,[1]운반비기준!$A$2:$D$3036,4,FALSE))) | O24: =IF(H24="","",(M24+N24)) | Q24: =IF(H24="","",(O24+P24)) | R24: =IF(E24="","",VLOOKUP(E24,[1]DATA!$A$2:$AG$2452,10,FALSE)) -> 삼일이노팩 | S24: =IF(E24="","",VLOOKUP(E24,[1]DATA!$A$2:$AG$2452,2,FALSE)) -> BOX
A25: =IF(E25="","",(A24+1)) -> 24 | B25: =IF(E25="","",(B24)) -> 46128 | C25: CJ대한통운/형제식품 | D25: 형제식품 | E25: SI-4.5K#2(컬리) | F25: 32 | I25: =IF(E25="","",VLOOKUP(E25,[1]DATA!$A$2:$AG$2452,5,FALSE)) -> 196 | J25: =IF(E25="","",(G25*I25/1000)) -> 0 | K25: =IF(E25="","",SUMIFS([2]단가!$E:$E,[2]단가!$A:$A,출하일보전송용260416!$C25,[2]단가!$B:$B,출하일보전송용260416!$E25)) -> #VALUE! | L25: =IF(E25="","",(G25*K25)) -> #VALUE! | M25: =IF(H25="","",IF(H25<50,VLOOKUP(C25,[1]운반비기준!$A$2:$D$3036,3,FALSE))) | N25: =IF(H25="","",IF(H25>51,VLOOKUP(C25,[1]운반비기준!$A$2:$D$3036,4,FALSE))) | O25: =IF(H25="","",(M25+N25)) | Q25: =IF(H25="","",(O25+P25)) | R25: =IF(E25="","",VLOOKUP(E25,[1]DATA!$A$2:$AG$2452,10,FALSE)) -> 삼일이노팩 | S25: =IF(E25="","",VLOOKUP(E25,[1]DATA!$A$2:$AG$2452,2,FALSE)) -> BOX
A26: =IF(E26="","",(A25+1)) -> 25 | B26: =IF(E26="","",(B25)) -> 46128 | C26: CJ대한통운/형제식품 | D26: 형제식품 | E26: KURLY-1#5 | F26: 260 | I26: =IF(E26="","",VLOOKUP(E26,[1]DATA!$A$2:$AG$2452,5,FALSE)) -> 79 | J26: =IF(E26="","",(G26*I26/1000)) -> 0 | K26: =IF(E26="","",SUMIFS([2]단가!$E:$E,[2]단가!$A:$A,출하일보전송용260416!$C26,[2]단가!$B:$B,출하일보전송용260416!$E26)) -> #VALUE! | L26: =IF(E26="","",(G26*K26)) -> #VALUE! | M26: =IF(H26="","",IF(H26<50,VLOOKUP(C26,[1]운반비기준!$A$2:$D$3036,3,FALSE))) | N26: =IF(H26="","",IF(H26>51,VLOOKUP(C26,[1]운반비기준!$A$2:$D$3036,4,FALSE))) | O26: =IF(H26="","",(M26+N26)) | Q26: =IF(H26="","",(O26+P26)) | R26: =IF(E26="","",VLOOKUP(E26,[1]DATA!$A$2:$AG$2452,10,FALSE)) -> 삼일이노팩 | S26: =IF(E26="","",VLOOKUP(E26,[1]DATA!$A$2:$AG$2452,2,FALSE)) -> BOX
A27: =IF(E27="","",(A26+1)) -> 26 | B27: =IF(E27="","",(B26)) -> 46128 | C27: CJ대한통운/도당 | D27: 김보람초코릿 | E27: SI-0.5K#2 | F27: 2632 | H27: 삼일2.5 | I27: =IF(E27="","",VLOOKUP(E27,[1]DATA!$A$2:$AG$2452,5,FALSE)) -> 53 | J27: =IF(E27="","",(G27*I27/1000)) -> 0 | K27: =IF(E27="","",SUMIFS([2]단가!$E:$E,[2]단가!$A:$A,출하일보전송용260416!$C27,[2]단가!$B:$B,출하일보전송용260416!$E27)) -> #VALUE! | L27: =IF(E27="","",(G27*K27)) -> #VALUE! | M27: =IF(H27="","",IF(H27<50,VLOOKUP(C27,[1]운반비기준!$A$2:$D$3036,3,FALSE))) -> FALSE | N27: 120000 | O27: =IF(H27="","",(M27+N27)) -> 120000 | Q27: =IF(H27="","",(O27+P27)) -> 120000 | R27: =IF(E27="","",VLOOKUP(E27,[1]DATA!$A$2:$AG$2452,10,FALSE)) -> 삼일이노팩 | S27: =IF(E27="","",VLOOKUP(E27,[1]DATA!$A$2:$AG$2452,2,FALSE)) -> BOX
A28: =IF(E28="","",(A27+1)) -> 27 | B28: =IF(E28="","",(B27)) -> 46128 | C28: 위닉스 | D28: 위닉스/화성 1층 | E28: 창문형에어컨-UP | F28: 800 | H28: 500 | I28: =IF(E28="","",VLOOKUP(E28,[1]DATA!$A$2:$AG$2452,5,FALSE)) -> 160 | J28: =IF(E28="","",(G28*I28/1000)) -> 0 | K28: =IF(E28="","",SUMIFS([2]단가!$E:$E,[2]단가!$A:$A,출하일보전송용260416!$C28,[2]단가!$B:$B,출하일보전송용260416!$E28)) -> #VALUE! | L28: =IF(E28="","",(G28*K28)) -> #VALUE! | M28: =IF(H28="","",IF(H28<50,VLOOKUP(C28,[1]운반비기준!$A$2:$D$3036,3,FALSE))) -> FALSE | N28: =IF(H28="","",IF(H28>51,VLOOKUP(C28,[1]운반비기준!$A$2:$D$3036,4,FALSE))) -> 100000 | O28: =IF(H28="","",(M28+N28)) -> 100000 | Q28: =IF(H28="","",(O28+P28)) -> 100000 | R28: =IF(E28="","",VLOOKUP(E28,[1]DATA!$A$2:$AG$2452,10,FALSE)) -> 위닉스 | S28: =IF(E28="","",VLOOKUP(E28,[1]DATA!$A$2:$AG$2452,2,FALSE)) -> SET
A29: =IF(E29="","",(A28+1)) -> 28 | B29: =IF(E29="","",(B28)) -> 46128 | C29: 위닉스 | D29: 위닉스/화성 1층 | E29: 창문형에어컨-UP | F29: 20 | H29: LOSS | I29: =IF(E29="","",VLOOKUP(E29,[1]DATA!$A$2:$AG$2452,5,FALSE)) -> 160 | J29: =IF(E29="","",(G29*I29/1000)) -> 0 | L29: =IF(E29="","",(G29*K29)) -> 0 | M29: =IF(H29="","",IF(H29<50,VLOOKUP(C29,[1]운반비기준!$A$2:$D$3036,3,FALSE))) -> FALSE | N29: =IF(H29="","",IF(H29>51,VLOOKUP(C29,[1]운반비기준!$A$2:$D$3036,4,FALSE))) -> 100000 | Q29: =IF(H29="","",(O29+P29)) -> 0 | R29: =IF(E29="","",VLOOKUP(E29,[1]DATA!$A$2:$AG$2452,10,FALSE)) -> 위닉스 | S29: =IF(E29="","",VLOOKUP(E29,[1]DATA!$A$2:$AG$2452,2,FALSE)) -> SET
A30: =IF(E30="","",(A29+1)) -> 29 | B30: =IF(E30="","",(B29)) -> 46128 | C30: 위닉스 | D30: 위닉스/화성 1층 | E30: 창문형에어컨-LOW | F30: 800 | I30: =IF(E30="","",VLOOKUP(E30,[1]DATA!$A$2:$AG$2452,5,FALSE)) -> 240 | J30: =IF(E30="","",(G30*I30/1000)) -> 0 | K30: =IF(E30="","",SUMIFS([2]단가!$E:$E,[2]단가!$A:$A,출하일보전송용260416!$C30,[2]단가!$B:$B,출하일보전송용260416!$E30)) -> #VALUE! | L30: =IF(E30="","",(G30*K30)) -> #VALUE! | M30: =IF(H30="","",IF(H30<50,VLOOKUP(C30,[1]운반비기준!$A$2:$D$3036,3,FALSE))) | N30: =IF(H30="","",IF(H30>51,VLOOKUP(C30,[1]운반비기준!$A$2:$D$3036,4,FALSE))) | O30: =IF(H30="","",(M30+N30)) | Q30: =IF(H30="","",(O30+P30)) | R30: =IF(E30="","",VLOOKUP(E30,[1]DATA!$A$2:$AG$2452,10,FALSE)) -> 위닉스 | S30: =IF(E30="","",VLOOKUP(E30,[1]DATA!$A$2:$AG$2452,2,FALSE)) -> SET
A31: =IF(E31="","",(A30+1)) -> 30 | B31: =IF(E31="","",(B30)) -> 46128 | C31: 위닉스 | D31: 위닉스/화성 1층 | E31: 창문형에어컨-LOW | F31: 20 | H31: LOSS | I31: =IF(E31="","",VLOOKUP(E31,[1]DATA!$A$2:$AG$2452,5,FALSE)) -> 240 | J31: =IF(E31="","",(G31*I31/1000)) -> 0 | L31: =IF(E31="","",(G31*K31)) -> 0 | M31: =IF(H31="","",IF(H31<50,VLOOKUP(C31,[1]운반비기준!$A$2:$D$3036,3,FALSE))) -> FALSE | N31: =IF(H31="","",IF(H31>51,VLOOKUP(C31,[1]운반비기준!$A$2:$D$3036,4,FALSE))) -> 100000 | Q31: =IF(H31="","",(O31+P31)) -> 0 | R31: =IF(E31="","",VLOOKUP(E31,[1]DATA!$A$2:$AG$2452,10,FALSE)) -> 위닉스 | S31: =IF(E31="","",VLOOKUP(E31,[1]DATA!$A$2:$AG$2452,2,FALSE)) -> SET
A32: =IF(E32="","",(A31+1)) -> 31 | B32: =IF(E32="","",(B31)) -> 46128 | C32: 에이텍 | D32: 에이텍 | E32: A2GL | F32: 200 | H32: 11 | I32: =IF(E32="","",VLOOKUP(E32,[1]DATA!$A$2:$AG$2452,5,FALSE)) -> 770 | J32: =IF(E32="","",(G32*I32/1000)) -> 0 | K32: =IF(E32="","",SUMIFS([2]단가!$E:$E,[2]단가!$A:$A,출하일보전송용260416!$C32,[2]단가!$B:$B,출하일보전송용260416!$E32)) -> #VALUE! | L32: =IF(E32="","",(G32*K32)) -> #VALUE! | M32: =IF(H32="","",IF(H32<50,VLOOKUP(C32,[1]운반비기준!$A$2:$D$3036,3,FALSE))) -> 61000 | N32: =IF(H32="","",IF(H32>51,VLOOKUP(C32,[1]운반비기준!$A$2:$D$3036,4,FALSE))) -> FALSE | O32: =IF(H32="","",(M32+N32)) -> 61000 | Q32: =IF(H32="","",(O32+P32)) -> 61000 | R32: =IF(E32="","",VLOOKUP(E32,[1]DATA!$A$2:$AG$2452,10,FALSE)) -> 에이텍 | S32: =IF(E32="","",VLOOKUP(E32,[1]DATA!$A$2:$AG$2452,2,FALSE)) -> SET
A33: =IF(E33="","",(A32+1)) -> 32 | B33: =IF(E33="","",(B32)) -> 46128 | C33: 한화테크윈 | D33: 한화테크윈 | E33: TBD | F33: 70 | H33: 5 | I33: =IF(E33="","",VLOOKUP(E33,[1]DATA!$A$2:$AG$2452,5,FALSE)) -> 95 | J33: =IF(E33="","",(G33*I33/1000)) -> 0 | K33: =IF(E33="","",SUMIFS([2]단가!$E:$E,[2]단가!$A:$A,출하일보전송용260416!$C33,[2]단가!$B:$B,출하일보전송용260416!$E33)) -> #VALUE! | L33: =IF(E33="","",(G33*K33)) -> #VALUE! | M33: =IF(H33="","",IF(H33<50,VLOOKUP(C33,[1]운반비기준!$A$2:$D$3036,3,FALSE))) -> 46000 | N33: =IF(H33="","",IF(H33>51,VLOOKUP(C33,[1]운반비기준!$A$2:$D$3036,4,FALSE))) -> FALSE | O33: =IF(H33="","",(M33+N33)) -> 46000 | Q33: =IF(H33="","",(O33+P33)) -> 46000 | R33: =IF(E33="","",VLOOKUP(E33,[1]DATA!$A$2:$AG$2452,10,FALSE)) -> 한화테크윈 | S33: =IF(E33="","",VLOOKUP(E33,[1]DATA!$A$2:$AG$2452,2,FALSE)) -> SET
A34: =IF(E34="","",(A33+1)) -> 33 | B34: =IF(E34="","",(B33)) -> 46128 | C34: 한화테크윈 | D34: 한화테크윈 | E34: QRN-830S | F34: 100 | I34: =IF(E34="","",VLOOKUP(E34,[1]DATA!$A$2:$AG$2452,5,FALSE)) -> 27 | J34: =IF(E34="","",(G34*I34/1000)) -> 0 | K34: =IF(E34="","",SUMIFS([2]단가!$E:$E,[2]단가!$A:$A,출하일보전송용260416!$C34,[2]단가!$B:$B,출하일보전송용260416!$E34)) -> #VALUE! | L34: =IF(E34="","",(G34*K34)) -> #VALUE! | M34: =IF(H34="","",IF(H34<50,VLOOKUP(C34,[1]운반비기준!$A$2:$D$3036,3,FALSE))) | N34: =IF(H34="","",IF(H34>51,VLOOKUP(C34,[1]운반비기준!$A$2:$D$3036,4,FALSE))) | O34: =IF(H34="","",(M34+N34)) | Q34: =IF(H34="","",(O34+P34)) | R34: =IF(E34="","",VLOOKUP(E34,[1]DATA!$A$2:$AG$2452,10,FALSE)) -> 한화테크윈 | S34: =IF(E34="","",VLOOKUP(E34,[1]DATA!$A$2:$AG$2452,2,FALSE)) -> SET
A35: =IF(E35="","",(A34+1)) -> 34 | B35: =IF(E35="","",(B34)) -> 46128 | C35: 한화테크윈 | D35: 한화테크윈 | E35: TNP-AXXX0RW TOP/BOT | F35: 60 | I35: =IF(E35="","",VLOOKUP(E35,[1]DATA!$A$2:$AG$2452,5,FALSE)) -> 875 | J35: =IF(E35="","",(G35*I35/1000)) -> 0 | K35: =IF(E35="","",SUMIFS([2]단가!$E:$E,[2]단가!$A:$A,출하일보전송용260416!$C35,[2]단가!$B:$B,출하일보전송용260416!$E35)) -> #VALUE! | L35: =IF(E35="","",(G35*K35)) -> #VALUE! | M35: =IF(H35="","",IF(H35<50,VLOOKUP(C35,[1]운반비기준!$A$2:$D$3036,3,FALSE))) | N35: =IF(H35="","",IF(H35>51,VLOOKUP(C35,[1]운반비기준!$A$2:$D$3036,4,FALSE))) | O35: =IF(H35="","",(M35+N35)) | Q35: =IF(H35="","",(O35+P35)) | R35: =IF(E35="","",VLOOKUP(E35,[1]DATA!$A$2:$AG$2452,10,FALSE)) -> 한화비전 | S35: =IF(E35="","",VLOOKUP(E35,[1]DATA!$A$2:$AG$2452,2,FALSE)) -> SET
A36: =IF(E36="","",(A35+1)) -> 35 | B36: =IF(E36="","",(B35)) -> 46128 | C36: SK매직 | D36: M100 | E36: A700-L/R | F36: 100 | H36: 528 | I36: =IF(E36="","",VLOOKUP(E36,[1]DATA!$A$2:$AG$2452,5,FALSE)) -> 309 | J36: =IF(E36="","",(G36*I36/1000)) -> 0 | K36: =IF(E36="","",SUMIFS([2]단가!$E:$E,[2]단가!$A:$A,출하일보전송용260416!$C36,[2]단가!$B:$B,출하일보전송용260416!$E36)) -> #VALUE! | L36: =IF(E36="","",(G36*K36)) -> #VALUE! | M36: =IF(H36="","",IF(H36<50,VLOOKUP(C36,[1]운반비기준!$A$2:$D$3036,3,FALSE))) -> FALSE | N36: =IF(H36="","",IF(H36>51,VLOOKUP(C36,[1]운반비기준!$A$2:$D$3036,4,FALSE))) -> 73000 | O36: =IF(H36="","",(M36+N36)) -> 73000 | Q36: =IF(H36="","",(O36+P36)) -> 73000 | R36: =IF(E36="","",VLOOKUP(E36,[1]DATA!$A$2:$AG$2452,10,FALSE)) -> SK매직 | S36: =IF(E36="","",VLOOKUP(E36,[1]DATA!$A$2:$AG$2452,2,FALSE)) -> SET
A37: =IF(E37="","",(A36+1)) -> 36 | B37: =IF(E37="","",(B36)) -> 46128 | C37: SK매직 | D37: M100 | E37: A700-BOT | F37: 100 | I37: =IF(E37="","",VLOOKUP(E37,[1]DATA!$A$2:$AG$2452,5,FALSE)) -> 120 | J37: =IF(E37="","",(G37*I37/1000)) -> 0 | K37: =IF(E37="","",SUMIFS([2]단가!$E:$E,[2]단가!$A:$A,출하일보전송용260416!$C37,[2]단가!$B:$B,출하일보전송용260416!$E37)) -> #VALUE! | L37: =IF(E37="","",(G37*K37)) -> #VALUE! | M37: =IF(H37="","",IF(H37<50,VLOOKUP(C37,[1]운반비기준!$A$2:$D$3036,3,FALSE))) | N37: =IF(H37="","",IF(H37>51,VLOOKUP(C37,[1]운반비기준!$A$2:$D$3036,4,FALSE))) | O37: =IF(H37="","",(M37+N37)) | Q37: =IF(H37="","",(O37+P37)) | R37: =IF(E37="","",VLOOKUP(E37,[1]DATA!$A$2:$AG$2452,10,FALSE)) -> SK매직 | S37: =IF(E37="","",VLOOKUP(E37,[1]DATA!$A$2:$AG$2452,2,FALSE)) -> SET
A38: =IF(E38="","",(A37+1)) -> 37 | B38: =IF(E38="","",(B37)) -> 46128 | C38: SK매직 | D38: M100 | E38: JAC115 T/B | F38: 1000 | I38: =IF(E38="","",VLOOKUP(E38,[1]DATA!$A$2:$AG$2452,5,FALSE)) -> 188 | J38: =IF(E38="","",(G38*I38/1000)) -> 0 | K38: =IF(E38="","",SUMIFS([2]단가!$E:$E,[2]단가!$A:$A,출하일보전송용260416!$C38,[2]단가!$B:$B,출하일보전송용260416!$E38)) -> #VALUE! | L38: =IF(E38="","",(G38*K38)) -> #VALUE! | M38: =IF(H38="","",IF(H38<50,VLOOKUP(C38,[1]운반비기준!$A$2:$D$3036,3,FALSE))) | N38: =IF(H38="","",IF(H38>51,VLOOKUP(C38,[1]운반비기준!$A$2:$D$3036,4,FALSE))) | O38: =IF(H38="","",(M38+N38)) | Q38: =IF(H38="","",(O38+P38)) | R38: =IF(E38="","",VLOOKUP(E38,[1]DATA!$A$2:$AG$2452,10,FALSE)) -> SK매직 | S38: =IF(E38="","",VLOOKUP(E38,[1]DATA!$A$2:$AG$2452,2,FALSE)) -> SET
A39: =IF(E39="","",(A38+1)) | B39: =IF(E39="","",(B38)) | I39: =IF(E39="","",VLOOKUP(E39,[1]DATA!$A$2:$AG$2452,5,FALSE)) | J39: =IF(E39="","",(G39*I39/1000)) | K39: =IF(E39="","",SUMIFS([2]단가!$E:$E,[2]단가!$A:$A,출하일보전송용260416!$C39,[2]단가!$B:$B,출하일보전송용260416!$E39)) | L39: =IF(E39="","",(G39*K39)) | M39: =IF(H39="","",IF(H39<50,VLOOKUP(C39,[1]운반비기준!$A$2:$D$3036,3,FALSE))) | N39: =IF(H39="","",IF(H39>51,VLOOKUP(C39,[1]운반비기준!$A$2:$D$3036,4,FALSE))) | O39: =IF(H39="","",(M39+N39)) | Q39: =IF(H39="","",(O39+P39)) | R39: =IF(E39="","",VLOOKUP(E39,[1]DATA!$A$2:$AG$2452,10,FALSE)) | S39: =IF(E39="","",VLOOKUP(E39,[1]DATA!$A$2:$AG$2452,2,FALSE))
A40: =IF(E40="","",(A39+1)) | B40: =IF(E40="","",(B39)) | I40: =IF(E40="","",VLOOKUP(E40,[1]DATA!$A$2:$AG$2452,5,FALSE)) | J40: =IF(E40="","",(G40*I40/1000)) | K40: =IF(E40="","",SUMIFS([2]단가!$E:$E,[2]단가!$A:$A,출하일보전송용260416!$C40,[2]단가!$B:$B,출하일보전송용260416!$E40)) | L40: =IF(E40="","",(G40*K40)) | M40: =IF(H40="","",IF(H40<50,VLOOKUP(C40,[1]운반비기준!$A$2:$D$3036,3,FALSE))) | N40: =IF(H40="","",IF(H40>51,VLOOKUP(C40,[1]운반비기준!$A$2:$D$3036,4,FALSE))) | O40: =IF(H40="","",(M40+N40)) | Q40: =IF(H40="","",(O40+P40)) | R40: =IF(E40="","",VLOOKUP(E40,[1]DATA!$A$2:$AG$2452,10,FALSE)) | S40: =IF(E40="","",VLOOKUP(E40,[1]DATA!$A$2:$AG$2452,2,FALSE))
...
